Workbook

Sheet INSTRUCTIONS
A1: STORE LABOR & SALES TRACKER | INSTRUCTIONS
B3: OVERVIEW
B4: Track and manage store labor and sales by department.
B5: Enter forecasts before the quarter. Update actuals as you go.
B6: The tracker tells you exactly where you stand and what to do.
B8: SHEET LAYOUT
B9: INSTRUCTIONS | C9: -> You are here
B10: DASHBOARD | C10: -> Quarter at a glance — start every check-in here
B11: MONTH 1–4 | C11: -> Full dept detail — Forecast, Actual & Variance
B12: Q1 SUMMARY | C12: -> Auto-totals all months. Full quarter view
B14: COLOR CODING
B15: INPUT CELLS | C15: The only cells you type in
B16: CALCULATED CELLS | C16: Auto-calculated. Do not edit
B17: LINKED CELLS | C17: Pulling from another sheet. Do not edit
B18: GOOD! | C18: You are making labor
B19: BAD! | C19: You are missing labor
B21: WHAT TO ENTER — FORECAST
B22: PROJECTED SALES | C22: Expected sales for that department that month
B23: LABOR % | C23: Target labor as a percentage of that department sales
B24: AVG HOURLY RATE | C24: Average hourly wage for that department
B26: FRONT END: No sales entry — Labor % is entered as % of total store sales.
B27: WEEKS IN QUARTER | C27: Enter 13 or 17 on the Q1 Summary page
B29: WHAT TO ENTER — ACTUALS
B30: ACTUAL SALES | C30: Real sales for that department that month
B31: ACTUAL LABOR % | C31: Real labor percentage based on what was spent
B32: ACTUAL HOURLY RATE | C32: Real average hourly rate paid that month
B34: AUTO-CALCULATED
B35: FORECAST LABOR $ | C35: Projected Sales x Labor %
B36: FORECAST HOURS | C36: Forecast Labor $ / Avg Hourly Rate
B37: ACTUAL LABOR $ | C37: Actual Sales x Actual Labor %
B38: ACTUAL HOURS USED | C38: Actual Labor $ / Actual Avg Hourly Rate
B39: AVG WAGE | C39: Actual Labor $ / Actual Hours Used
B40: LABOR $ VARIANCE | C40: Actual Labor $ vs Forecast Labor $
B41: HOURS TO TRIM / AVAILABLE | C41: Labor $ Variance / Avg Hourly Rate
B42: STORE WEIGHTED LAB% | C42: Total Store Labor $ / Total Store Sales
B43: STORE AVG WAGE | C43: Total Store Labor $ / Total Store Hours Used
B44: WEEKLY AVG SALES | C44: Q1 Total Sales / Weeks in Quarter
B45: FRONT END LABOR $ | C45: Front End Lab% x Total Store Sales
B47: QUARTERLY SETUP
B48: [x] Download and rename the file (e.g. Store_1234_Q2_2025.xlsx)
...

Sheet DASHBOARD
A1: STORE LABOR & SALES TRACKER | QUARTERLY DASHBOARD
A3: QUARTER AT A GLANCE
B4: Q1 FORECAST | C4: Q1 ACTUAL | D4: VARIANCE | E4: STATUS
A5: TOTAL SALES | B5: ='Q1 SUMMARY'!B19 -> 6189740 | C5: ='Q1 SUMMARY'!C19 -> 0 | D5: ='Q1 SUMMARY'!H19 -> -797857.49
A6: TOTAL LABOR $ | B6: ='Q1 SUMMARY'!D19 -> 797857.49 | C6: ='Q1 SUMMARY'!E19 -> 0 | D6: ='Q1 SUMMARY'!H19 -> -797857.49 | E6: ='Q1 SUMMARY'!K19 -> GOOD!
A7: LABOR % | B7: ='Q1 SUMMARY'!F19 -> 0.1289 | C7: ='Q1 SUMMARY'!G19 -> 0 | D7: ='Q1 SUMMARY'!I19 -> -0.1289 | E7: ='Q1 SUMMARY'!K19 -> GOOD!
A8: WEEKLY AVG SALES | B8: ='Q1 SUMMARY'!J19 -> 0 | C8: "-" | D8: "-"
A9: STORE AVG WAGE | B9: "-" | C9: ='Q1 SUMMARY'!C21 -> 0 | D9: "-"
A11: DEPARTMENT SCORECARD
A12: DEPARTMENT | B12: Q1 FORECAST LAB$ | C12: Q1 ACTUAL LAB$ | D12: ACTUAL LAB% | E12: STATUS | F12: Q1 ACTION
A13: GROCERY | B13: ='Q1 SUMMARY'!D8 -> 329604.15 | C13: ='Q1 SUMMARY'!E8 -> 0 | D13: ='Q1 SUMMARY'!G8 -> 0 | E13: ='Q1 SUMMARY'!K8 -> GOOD! | F13: ='Q1 SUMMARY'!L8 -> ROOM FOR 13,184 HRS IF NEEDED
A14: MEAT | B14: ='Q1 SUMMARY'!D9 -> 71002.8 | C14: ='Q1 SUMMARY'!E9 -> 0 | D14: ='Q1 SUMMARY'!G9 -> 0 | E14: ='Q1 SUMMARY'!K9 -> GOOD! | F14: ='Q1 SUMMARY'!L9 -> ROOM FOR 2,840 HRS IF NEEDED
A15: SEAFOOD | B15: ='Q1 SUMMARY'!D10 -> 52707.6 | C15: ='Q1 SUMMARY'!E10 -> 0 | D15: ='Q1 SUMMARY'!G10 -> 0 | E15: ='Q1 SUMMARY'!K10 -> GOOD! | F15: ='Q1 SUMMARY'!L10 -> ROOM FOR 2,108 HRS IF NEEDED
A16: PRODUCE | B16: ='Q1 SUMMARY'!D11 -> 71002.8 | C16: ='Q1 SUMMARY'!E11 -> 0 | D16: ='Q1 SUMMARY'!G11 -> 0 | E16: ='Q1 SUMMARY'!K11 -> GOOD! | F16: ='Q1 SUMMARY'!L11 -> ROOM FOR 2,840 HRS IF NEEDED
A17: DELI | B17: ='Q1 SUMMARY'!D12 -> 57354.145 | C17: ='Q1 SUMMARY'!E12 -> 0 | D17: ='Q1 SUMMARY'!G12 -> 0 | E17: ='Q1 SUMMARY'!K12 -> GOOD! | F17: ='Q1 SUMMARY'!L12 -> ROOM FOR 2,294 HRS IF NEEDED
A18: BAKERY | B18: ='Q1 SUMMARY'!D13 -> 57354.145 | C18: ='Q1 SUMMARY'!E13 -> 0 | D18: ='Q1 SUMMARY'!G13 -> 0 | E18: ='Q1 SUMMARY'!K13 -> GOOD! | F18: ='Q1 SUMMARY'!L13 -> ROOM FOR 2,294 HRS IF NEEDED
A19: FLORAL | B19: ='Q1 SUMMARY'!D14 -> 3339.7452 | C19: ='Q1 SUMMARY'!E14 -> 0 | D19: ='Q1 SUMMARY'!G14 -> 0 | E19: ='Q1 SUMMARY'!K14 -> GOOD! | F19: ='Q1 SUMMARY'!L14 -> ROOM FOR 134 HRS IF NEEDED
A20: STARBUCKS | B20: ='Q1 SUMMARY'!D15 -> 1350.36 | C20: ='Q1 SUMMARY'!E15 -> 0 | D20: ='Q1 SUMMARY'!G15 -> 0 | E20: ='Q1 SUMMARY'!K15 -> GOOD! | F20: ='Q1 SUMMARY'!L15 -> ROOM FOR 54 HRS IF NEEDED
A21: ECOM | B21: ='Q1 SUMMARY'!D16 -> 30346.945 | C21: ='Q1 SUMMARY'!E16 -> 0 | D21: ='Q1 SUMMARY'!G16 -> 0 | E21: ='Q1 SUMMARY'!K16 -> GOOD! | F21: ='Q1 SUMMARY'!L16 -> ROOM FOR 1,214 HRS IF NEEDED
A22: FRONT END | B22: ='Q1 SUMMARY'!D17 -> 123794.8 | C22: ='Q1 SUMMARY'!E17 -> 0 | D22: ='Q1 SUMMARY'!G17 -> 0 | E22: ='Q1 SUMMARY'!K17 -> GOOD! | F22: ='Q1 SUMMARY'!L17 -> ROOM FOR 4,952 HRS IF NEEDED
A24: STORE TOTAL | B24: ='Q1 SUMMARY'!D19 -> 797857.49 | C24: ='Q1 SUMMARY'!E19 -> 0 | D24: ='Q1 SUMMARY'!G19 -> 0 | E24: ='Q1 SUMMARY'!K19 -> GOOD! | F24: ='Q1 SUMMARY'!L19 -> ROOM FOR 31,914 HRS IF NEEDED

Sheet MONTH 1
A1: MONTH 1 | STORE LABOR & SALES TRACKER
A3: STORE AT A GLANCE
B4: FORECAST | C4: ACTUAL | D4: VARIANCE | E4: STATUS
A5: TOTAL SALES | B5: =B82 -> 1547435 | C5: =B83 -> 0 | D5: =IFERROR(B83-B82,0) -> -1547435 | E5: =IF(B83>=B82,"GOOD!","BELOW PLAN") -> BELOW PLAN
A6: TOTAL LABOR $ | B6: =E82 -> 199464.37 | C6: =E83 -> 0 | D6: =IFERROR(E83-E82,0) -> -199464.37 | E6: =H84 -> GOOD!
A7: LABOR % | B7: =C82 -> 0.1289 | C7: =C83 -> 0 | D7: =IFERROR(C83-C82,0) -> -0.1289 | E7: =H84 -> GOOD!
A8: STORE AVG WAGE | B8: "-" | C8: =G83 -> 0 | D8: "-"
A9: TOTAL HOURS | B9: =F82 -> 7978.5749 | C9: =F83 -> 0 | D9: =IFERROR(F83-F82,0) -> -7978.5749 | E9: =H84 -> GOOD!
A12: DEPARTMENT SUMMARY
A13: DEPARTMENT | B13: FORECAST LAB$ | C13: ACTUAL LAB$ | D13: ACTUAL LAB% | E13: VAR LAB$ | F13: VAR LAB% | G13: STATUS | H13: ACTION
A14: GROCERY | B14: =E31 -> 82401.036 | C14: =E32 -> 0 | D14: =C32 -> 0 | E14: =E33 -> -82401.036 | F14: =C33 -> -0.1089 | G14: =H33 -> GOOD! | H14: =I33 -> ROOM FOR 3,296 HRS IF NEEDED
A15: MEAT | B15: =E36 -> 17750.7 | C15: =E37 -> 0 | D15: =C37 -> 0 | E15: =E38 -> -17750.7 | F15: =C38 -> -0.1089 | G15: =H38 -> GOOD! | H15: =I38 -> ROOM FOR 710 HRS IF NEEDED
A16: SEAFOOD | B16: =E41 -> 13176.9 | C16: =E42 -> 0 | D16: =C42 -> 0 | E16: =E43 -> -13176.9 | F16: =C43 -> -0.1089 | G16: =H43 -> GOOD! | H16: =I43 -> ROOM FOR 527 HRS IF NEEDED
A17: PRODUCE | B17: =E46 -> 17750.7 | C17: =E47 -> 0 | D17: =C47 -> 0 | E17: =E48 -> -17750.7 | F17: =C48 -> -0.1089 | G17: =H48 -> GOOD! | H17: =I48 -> ROOM FOR 710 HRS IF NEEDED
A18: DELI | B18: =E51 -> 14338.536 | C18: =E52 -> 0 | D18: =C52 -> 0 | E18: =E53 -> -14338.536 | F18: =C53 -> -0.1089 | G18: =H53 -> GOOD! | H18: =I53 -> ROOM FOR 574 HRS IF NEEDED
A19: BAKERY | B19: =E56 -> 14338.536 | C19: =E57 -> 0 | D19: =C57 -> 0 | E19: =E58 -> -14338.536 | F19: =C58 -> -0.1089 | G19: =H58 -> GOOD! | H19: =I58 -> ROOM FOR 574 HRS IF NEEDED
A20: FLORAL | B20: =E61 -> 834.9363 | C20: =E62 -> 0 | D20: =C62 -> 0 | E20: =E63 -> -834.9363 | F20: =C63 -> -0.1089 | G20: =H63 -> GOOD! | H20: =I63 -> ROOM FOR 33 HRS IF NEEDED
A21: STARBUCKS | B21: =E66 -> 337.59 | C21: =E67 -> 0 | D21: =C67 -> 0 | E21: =E68 -> -337.59 | F21: =C68 -> -0.1089 | G21: =H68 -> GOOD! | H21: =I68 -> ROOM FOR 14 HRS IF NEEDED
A22: ECOM | B22: =E71 -> 7586.7363 | C22: =E72 -> 0 | D22: =C72 -> 0 | E22: =E73 -> -7586.7363 | F22: =C73 -> -0.1089 | G22: =H73 -> GOOD! | H22: =I73 -> ROOM FOR 303 HRS IF NEEDED
A23: FRONT END | B23: =E76 -> 30948.7 | C23: =E77 -> 0 | D23: =C77 -> 0 | E23: =E78 -> -30948.7 | F23: =C78 -> -0.02 | G23: =H78 -> GOOD! | H23: =I78 -> ROOM FOR 1,238 HRS IF NEEDED
A24: STORE TOTAL | B24: =E82 -> 199464.37 | C24: =E83 -> 0 | D24: =C83 -> 0 | E24: =E84 -> -199464.37 | F24: =C84 -> -0.1289 | G24: =H84 -> GOOD! | H24: =I84 -> ROOM FOR 7,979 HRS IF NEEDED
A28: FULL DEPARTMENT DETAIL
B29: SALES | C29: LABOR % | D29: HRLY RATE | E29: LABOR $ | F29: HOURS | G29: AVG WAGE | H29: STATUS | I29: ACTION
A30: GROCERY
A31: FORECAST | B31: 756667 | C31: 0.1089 | D31: 25 | E31: =IFERROR(B31*C31,0) -> 82401.036 | F31: =IFERROR(E31/D31,0) -> 3296.0415
A32: ACTUAL | E32: =IFERROR(B32*C32,0) -> 0 | F32: =IFERROR(E32/D32,0) -> 0 | G32: =IFERROR(E32/F32,0) -> 0
A33: VARIANCE | B33: =IFERROR(B32-B31,0) -> -756667 | C33: =IFERROR(C32-C31,0) -> -0.1089 | E33: =IFERROR(E32-E31,0) -> -82401.036 | H33: =IF(E33=0,"-",IF(C33<=0,"GOOD!",IF(C33<=0.01,"CAUTION!","BAD!"))) -> GOOD! | I33: =IFERROR(IF(E33>0,"TRIM "&TEXT(ABS(E33)/D31,"#,##0")&" HRS TO HIT TARGET","ROOM FOR "&TEXT(ABS(E33)/D31,"#,##0")&" HRS IF NEEDED"),"-") -> ROOM FOR 3,296 HRS IF NEEDED
A35: MEAT
A36: FORECAST | B36: 163000 | C36: 0.1089 | D36: 25 | E36: =IFERROR(B36*C36,0) -> 17750.7 | F36: =IFERROR(E36/D36,0) -> 710.028
A37: ACTUAL | E37: =IFERROR(B37*C37,0) -> 0 | F37: =IFERROR(E37/D37,0) -> 0 | G37: =IFERROR(E37/F37,0) -> 0
A38: VARIANCE | B38: =IFERROR(B37-B36,0) -> -163000 | C38: =IFERROR(C37-C36,0) -> -0.1089 | E38: =IFERROR(E37-E36,0) -> -17750.7 | H38: =IF(E38=0,"-",IF(C38<=0,"GOOD!",IF(C38<=0.01,"CAUTION!","BAD!"))) -> GOOD! | I38: =IFERROR(IF(E38>0,"TRIM "&TEXT(ABS(E38)/D36,"#,##0")&" HRS TO HIT TARGET","ROOM FOR "&TEXT(ABS(E38)/D36,"#,##0")&" HRS IF NEEDED"),"-") -> ROOM FOR 710 HRS IF NEEDED
A40: SEAFOOD
A41: FORECAST | B41: 121000 | C41: 0.1089 | D41: 25 | E41: =IFERROR(B41*C41,0) -> 13176.9 | F41: =IFERROR(E41/D41,0) -> 527.076
A42: ACTUAL | E42: =IFERROR(B42*C42,0) -> 0 | F42: =IFERROR(E42/D42,0) -> 0 | G42: =IFERROR(E42/F42,0) -> 0
A43: VARIANCE | B43: =IFERROR(B42-B41,0) -> -121000 | C43: =IFERROR(C42-C41,0) -> -0.1089 | E43: =IFERROR(E42-E41,0) -> -13176.9 | H43: =IF(E43=0,"-",IF(C43<=0,"GOOD!",IF(C43<=0.01,"CAUTION!","BAD!"))) -> GOOD! | I43: =IFERROR(IF(E43>0,"TRIM "&TEXT(ABS(E43)/D41,"#,##0")&" HRS TO HIT TARGET","ROOM FOR "&TEXT(ABS(E43)/D41,"#,##0")&" HRS IF NEEDED"),"-") -> ROOM FOR 527 HRS IF NEEDED
A45: PRODUCE
A46: FORECAST | B46: 163000 | C46: 0.1089 | D46: 25 | E46: =IFERROR(B46*C46,0) -> 17750.7 | F46: =IFERROR(E46/D46,0) -> 710.028
A47: ACTUAL | E47: =IFERROR(B47*C47,0) -> 0 | F47: =IFERROR(E47/D47,0) -> 0 | G47: =IFERROR(E47/F47,0) -> 0
A48: VARIANCE | B48: =IFERROR(B47-B46,0) -> -163000 | C48: =IFERROR(C47-C46,0) -> -0.1089 | E48: =IFERROR(E47-E46,0) -> -17750.7 | H48: =IF(E48=0,"-",IF(C48<=0,"GOOD!",IF(C48<=0.01,"CAUTION!","BAD!"))) -> GOOD! | I48: =IFERROR(IF(E48>0,"TRIM "&TEXT(ABS(E48)/D46,"#,##0")&" HRS TO HIT TARGET","ROOM FOR "&TEXT(ABS(E48)/D46,"#,##0")&" HRS IF NEEDED"),"-") -> ROOM FOR 710 HRS IF NEEDED
A50: DELI
...

Sheet MONTH 2
A1: MONTH 2 | STORE LABOR & SALES TRACKER
A3: STORE AT A GLANCE
B4: FORECAST | C4: ACTUAL | D4: VARIANCE | E4: STATUS
A5: TOTAL SALES | B5: =B82 -> 1547435 | C5: =B83 -> 0 | D5: =IFERROR(B83-B82,0) -> -1547435 | E5: =IF(B83>=B82,"GOOD!","BELOW PLAN") -> BELOW PLAN
A6: TOTAL LABOR $ | B6: =E82 -> 199464.37 | C6: =E83 -> 0 | D6: =IFERROR(E83-E82,0) -> -199464.37 | E6: =H84 -> GOOD!
A7: LABOR % | B7: =C82 -> 0.1289 | C7: =C83 -> 0 | D7: =IFERROR(C83-C82,0) -> -0.1289 | E7: =H84 -> GOOD!
A8: STORE AVG WAGE | B8: "-" | C8: =G83 -> 0 | D8: "-"
A9: TOTAL HOURS | B9: =F82 -> 7978.5749 | C9: =F83 -> 0 | D9: =IFERROR(F83-F82,0) -> -7978.5749 | E9: =H84 -> GOOD!
A12: DEPARTMENT SUMMARY
A13: DEPARTMENT | B13: FORECAST LAB$ | C13: ACTUAL LAB$ | D13: ACTUAL LAB% | E13: VAR LAB$ | F13: VAR LAB% | G13: STATUS | H13: ACTION
A14: GROCERY | B14: =E31 -> 82401.036 | C14: =E32 -> 0 | D14: =C32 -> 0 | E14: =E33 -> -82401.036 | F14: =C33 -> -0.1089 | G14: =H33 -> GOOD! | H14: =I33 -> ROOM FOR 3,296 HRS IF NEEDED
A15: MEAT | B15: =E36 -> 17750.7 | C15: =E37 -> 0 | D15: =C37 -> 0 | E15: =E38 -> -17750.7 | F15: =C38 -> -0.1089 | G15: =H38 -> GOOD! | H15: =I38 -> ROOM FOR 710 HRS IF NEEDED
A16: SEAFOOD | B16: =E41 -> 13176.9 | C16: =E42 -> 0 | D16: =C42 -> 0 | E16: =E43 -> -13176.9 | F16: =C43 -> -0.1089 | G16: =H43 -> GOOD! | H16: =I43 -> ROOM FOR 527 HRS IF NEEDED
A17: PRODUCE | B17: =E46 -> 17750.7 | C17: =E47 -> 0 | D17: =C47 -> 0 | E17: =E48 -> -17750.7 | F17: =C48 -> -0.1089 | G17: =H48 -> GOOD! | H17: =I48 -> ROOM FOR 710 HRS IF NEEDED
A18: DELI | B18: =E51 -> 14338.536 | C18: =E52 -> 0 | D18: =C52 -> 0 | E18: =E53 -> -14338.536 | F18: =C53 -> -0.1089 | G18: =H53 -> GOOD! | H18: =I53 -> ROOM FOR 574 HRS IF NEEDED
A19: BAKERY | B19: =E56 -> 14338.536 | C19: =E57 -> 0 | D19: =C57 -> 0 | E19: =E58 -> -14338.536 | F19: =C58 -> -0.1089 | G19: =H58 -> GOOD! | H19: =I58 -> ROOM FOR 574 HRS IF NEEDED
A20: FLORAL | B20: =E61 -> 834.9363 | C20: =E62 -> 0 | D20: =C62 -> 0 | E20: =E63 -> -834.9363 | F20: =C63 -> -0.1089 | G20: =H63 -> GOOD! | H20: =I63 -> ROOM FOR 33 HRS IF NEEDED
A21: STARBUCKS | B21: =E66 -> 337.59 | C21: =E67 -> 0 | D21: =C67 -> 0 | E21: =E68 -> -337.59 | F21: =C68 -> -0.1089 | G21: =H68 -> GOOD! | H21: =I68 -> ROOM FOR 14 HRS IF NEEDED
A22: ECOM | B22: =E71 -> 7586.7363 | C22: =E72 -> 0 | D22: =C72 -> 0 | E22: =E73 -> -7586.7363 | F22: =C73 -> -0.1089 | G22: =H73 -> GOOD! | H22: =I73 -> ROOM FOR 303 HRS IF NEEDED
A23: FRONT END | B23: =E76 -> 30948.7 | C23: =E77 -> 0 | D23: =C77 -> 0 | E23: =E78 -> -30948.7 | F23: =C78 -> -0.02 | G23: =H78 -> GOOD! | H23: =I78 -> ROOM FOR 1,238 HRS IF NEEDED
A24: STORE TOTAL | B24: =E82 -> 199464.37 | C24: =E83 -> 0 | D24: =C83 -> 0 | E24: =E84 -> -199464.37 | F24: =C84 -> -0.1289 | G24: =H84 -> GOOD! | H24: =I84 -> ROOM FOR 7,979 HRS IF NEEDED
A28: FULL DEPARTMENT DETAIL
B29: SALES | C29: LABOR % | D29: HRLY RATE | E29: LABOR $ | F29: HOURS | G29: AVG WAGE | H29: STATUS | I29: ACTION
A30: GROCERY
A31: FORECAST | B31: 756667 | C31: 0.1089 | D31: 25 | E31: =IFERROR(B31*C31,0) -> 82401.036 | F31: =IFERROR(E31/D31,0) -> 3296.0415
A32: ACTUAL | E32: =IFERROR(B32*C32,0) -> 0 | F32: =IFERROR(E32/D32,0) -> 0 | G32: =IFERROR(E32/F32,0) -> 0
A33: VARIANCE | B33: =IFERROR(B32-B31,0) -> -756667 | C33: =IFERROR(C32-C31,0) -> -0.1089 | E33: =IFERROR(E32-E31,0) -> -82401.036 | H33: =IF(E33=0,"-",IF(C33<=0,"GOOD!",IF(C33<=0.01,"CAUTION!","BAD!"))) -> GOOD! | I33: =IFERROR(IF(E33>0,"TRIM "&TEXT(ABS(E33)/D31,"#,##0")&" HRS TO HIT TARGET","ROOM FOR "&TEXT(ABS(E33)/D31,"#,##0")&" HRS IF NEEDED"),"-") -> ROOM FOR 3,296 HRS IF NEEDED
A35: MEAT
A36: FORECAST | B36: 163000 | C36: 0.1089 | D36: 25 | E36: =IFERROR(B36*C36,0) -> 17750.7 | F36: =IFERROR(E36/D36,0) -> 710.028
A37: ACTUAL | E37: =IFERROR(B37*C37,0) -> 0 | F37: =IFERROR(E37/D37,0) -> 0 | G37: =IFERROR(E37/F37,0) -> 0
A38: VARIANCE | B38: =IFERROR(B37-B36,0) -> -163000 | C38: =IFERROR(C37-C36,0) -> -0.1089 | E38: =IFERROR(E37-E36,0) -> -17750.7 | H38: =IF(E38=0,"-",IF(C38<=0,"GOOD!",IF(C38<=0.01,"CAUTION!","BAD!"))) -> GOOD! | I38: =IFERROR(IF(E38>0,"TRIM "&TEXT(ABS(E38)/D36,"#,##0")&" HRS TO HIT TARGET","ROOM FOR "&TEXT(ABS(E38)/D36,"#,##0")&" HRS IF NEEDED"),"-") -> ROOM FOR 710 HRS IF NEEDED
A40: SEAFOOD
A41: FORECAST | B41: 121000 | C41: 0.1089 | D41: 25 | E41: =IFERROR(B41*C41,0) -> 13176.9 | F41: =IFERROR(E41/D41,0) -> 527.076
A42: ACTUAL | E42: =IFERROR(B42*C42,0) -> 0 | F42: =IFERROR(E42/D42,0) -> 0 | G42: =IFERROR(E42/F42,0) -> 0
A43: VARIANCE | B43: =IFERROR(B42-B41,0) -> -121000 | C43: =IFERROR(C42-C41,0) -> -0.1089 | E43: =IFERROR(E42-E41,0) -> -13176.9 | H43: =IF(E43=0,"-",IF(C43<=0,"GOOD!",IF(C43<=0.01,"CAUTION!","BAD!"))) -> GOOD! | I43: =IFERROR(IF(E43>0,"TRIM "&TEXT(ABS(E43)/D41,"#,##0")&" HRS TO HIT TARGET","ROOM FOR "&TEXT(ABS(E43)/D41,"#,##0")&" HRS IF NEEDED"),"-") -> ROOM FOR 527 HRS IF NEEDED
A45: PRODUCE
A46: FORECAST | B46: 163000 | C46: 0.1089 | D46: 25 | E46: =IFERROR(B46*C46,0) -> 17750.7 | F46: =IFERROR(E46/D46,0) -> 710.028
A47: ACTUAL | E47: =IFERROR(B47*C47,0) -> 0 | F47: =IFERROR(E47/D47,0) -> 0 | G47: =IFERROR(E47/F47,0) -> 0
A48: VARIANCE | B48: =IFERROR(B47-B46,0) -> -163000 | C48: =IFERROR(C47-C46,0) -> -0.1089 | E48: =IFERROR(E47-E46,0) -> -17750.7 | H48: =IF(E48=0,"-",IF(C48<=0,"GOOD!",IF(C48<=0.01,"CAUTION!","BAD!"))) -> GOOD! | I48: =IFERROR(IF(E48>0,"TRIM "&TEXT(ABS(E48)/D46,"#,##0")&" HRS TO HIT TARGET","ROOM FOR "&TEXT(ABS(E48)/D46,"#,##0")&" HRS IF NEEDED"),"-") -> ROOM FOR 710 HRS IF NEEDED
A50: DELI
...

Sheet MONTH 3
A1: MONTH 3 | STORE LABOR & SALES TRACKER
A3: STORE AT A GLANCE
B4: FORECAST | C4: ACTUAL | D4: VARIANCE | E4: STATUS
A5: TOTAL SALES | B5: =B82 -> 1547435 | C5: =B83 -> 0 | D5: =IFERROR(B83-B82,0) -> -1547435 | E5: =IF(B83>=B82,"GOOD!","BELOW PLAN") -> BELOW PLAN
A6: TOTAL LABOR $ | B6: =E82 -> 199464.37 | C6: =E83 -> 0 | D6: =IFERROR(E83-E82,0) -> -199464.37 | E6: =H84 -> GOOD!
A7: LABOR % | B7: =C82 -> 0.1289 | C7: =C83 -> 0 | D7: =IFERROR(C83-C82,0) -> -0.1289 | E7: =H84 -> GOOD!
A8: STORE AVG WAGE | B8: "-" | C8: =G83 -> 0 | D8: "-"
A9: TOTAL HOURS | B9: =F82 -> 7978.5749 | C9: =F83 -> 0 | D9: =IFERROR(F83-F82,0) -> -7978.5749 | E9: =H84 -> GOOD!
A12: DEPARTMENT SUMMARY
A13: DEPARTMENT | B13: FORECAST LAB$ | C13: ACTUAL LAB$ | D13: ACTUAL LAB% | E13: VAR LAB$ | F13: VAR LAB% | G13: STATUS | H13: ACTION
A14: GROCERY | B14: =E31 -> 82401.036 | C14: =E32 -> 0 | D14: =C32 -> 0 | E14: =E33 -> -82401.036 | F14: =C33 -> -0.1089 | G14: =H33 -> GOOD! | H14: =I33 -> ROOM FOR 3,296 HRS IF NEEDED
A15: MEAT | B15: =E36 -> 17750.7 | C15: =E37 -> 0 | D15: =C37 -> 0 | E15: =E38 -> -17750.7 | F15: =C38 -> -0.1089 | G15: =H38 -> GOOD! | H15: =I38 -> ROOM FOR 710 HRS IF NEEDED
A16: SEAFOOD | B16: =E41 -> 13176.9 | C16: =E42 -> 0 | D16: =C42 -> 0 | E16: =E43 -> -13176.9 | F16: =C43 -> -0.1089 | G16: =H43 -> GOOD! | H16: =I43 -> ROOM FOR 527 HRS IF NEEDED
A17: PRODUCE | B17: =E46 -> 17750.7 | C17: =E47 -> 0 | D17: =C47 -> 0 | E17: =E48 -> -17750.7 | F17: =C48 -> -0.1089 | G17: =H48 -> GOOD! | H17: =I48 -> ROOM FOR 710 HRS IF NEEDED
A18: DELI | B18: =E51 -> 14338.536 | C18: =E52 -> 0 | D18: =C52 -> 0 | E18: =E53 -> -14338.536 | F18: =C53 -> -0.1089 | G18: =H53 -> GOOD! | H18: =I53 -> ROOM FOR 574 HRS IF NEEDED
A19: BAKERY | B19: =E56 -> 14338.536 | C19: =E57 -> 0 | D19: =C57 -> 0 | E19: =E58 -> -14338.536 | F19: =C58 -> -0.1089 | G19: =H58 -> GOOD! | H19: =I58 -> ROOM FOR 574 HRS IF NEEDED
A20: FLORAL | B20: =E61 -> 834.9363 | C20: =E62 -> 0 | D20: =C62 -> 0 | E20: =E63 -> -834.9363 | F20: =C63 -> -0.1089 | G20: =H63 -> GOOD! | H20: =I63 -> ROOM FOR 33 HRS IF NEEDED
A21: STARBUCKS | B21: =E66 -> 337.59 | C21: =E67 -> 0 | D21: =C67 -> 0 | E21: =E68 -> -337.59 | F21: =C68 -> -0.1089 | G21: =H68 -> GOOD! | H21: =I68 -> ROOM FOR 14 HRS IF NEEDED
A22: ECOM | B22: =E71 -> 7586.7363 | C22: =E72 -> 0 | D22: =C72 -> 0 | E22: =E73 -> -7586.7363 | F22: =C73 -> -0.1089 | G22: =H73 -> GOOD! | H22: =I73 -> ROOM FOR 303 HRS IF NEEDED
A23: FRONT END | B23: =E76 -> 30948.7 | C23: =E77 -> 0 | D23: =C77 -> 0 | E23: =E78 -> -30948.7 | F23: =C78 -> -0.02 | G23: =H78 -> GOOD! | H23: =I78 -> ROOM FOR 1,238 HRS IF NEEDED
A24: STORE TOTAL | B24: =E82 -> 199464.37 | C24: =E83 -> 0 | D24: =C83 -> 0 | E24: =E84 -> -199464.37 | F24: =C84 -> -0.1289 | G24: =H84 -> GOOD! | H24: =I84 -> ROOM FOR 7,979 HRS IF NEEDED
A28: FULL DEPARTMENT DETAIL
B29: SALES | C29: LABOR % | D29: HRLY RATE | E29: LABOR $ | F29: HOURS | G29: AVG WAGE | H29: STATUS | I29: ACTION
A30: GROCERY
A31: FORECAST | B31: 756667 | C31: 0.1089 | D31: 25 | E31: =IFERROR(B31*C31,0) -> 82401.036 | F31: =IFERROR(E31/D31,0) -> 3296.0415
A32: ACTUAL | E32: =IFERROR(B32*C32,0) -> 0 | F32: =IFERROR(E32/D32,0) -> 0 | G32: =IFERROR(E32/F32,0) -> 0
A33: VARIANCE | B33: =IFERROR(B32-B31,0) -> -756667 | C33: =IFERROR(C32-C31,0) -> -0.1089 | E33: =IFERROR(E32-E31,0) -> -82401.036 | H33: =IF(E33=0,"-",IF(C33<=0,"GOOD!",IF(C33<=0.01,"CAUTION!","BAD!"))) -> GOOD! | I33: =IFERROR(IF(E33>0,"TRIM "&TEXT(ABS(E33)/D31,"#,##0")&" HRS TO HIT TARGET","ROOM FOR "&TEXT(ABS(E33)/D31,"#,##0")&" HRS IF NEEDED"),"-") -> ROOM FOR 3,296 HRS IF NEEDED
A35: MEAT
A36: FORECAST | B36: 163000 | C36: 0.1089 | D36: 25 | E36: =IFERROR(B36*C36,0) -> 17750.7 | F36: =IFERROR(E36/D36,0) -> 710.028
A37: ACTUAL | E37: =IFERROR(B37*C37,0) -> 0 | F37: =IFERROR(E37/D37,0) -> 0 | G37: =IFERROR(E37/F37,0) -> 0
A38: VARIANCE | B38: =IFERROR(B37-B36,0) -> -163000 | C38: =IFERROR(C37-C36,0) -> -0.1089 | E38: =IFERROR(E37-E36,0) -> -17750.7 | H38: =IF(E38=0,"-",IF(C38<=0,"GOOD!",IF(C38<=0.01,"CAUTION!","BAD!"))) -> GOOD! | I38: =IFERROR(IF(E38>0,"TRIM "&TEXT(ABS(E38)/D36,"#,##0")&" HRS TO HIT TARGET","ROOM FOR "&TEXT(ABS(E38)/D36,"#,##0")&" HRS IF NEEDED"),"-") -> ROOM FOR 710 HRS IF NEEDED
A40: SEAFOOD
A41: FORECAST | B41: 121000 | C41: 0.1089 | D41: 25 | E41: =IFERROR(B41*C41,0) -> 13176.9 | F41: =IFERROR(E41/D41,0) -> 527.076
A42: ACTUAL | E42: =IFERROR(B42*C42,0) -> 0 | F42: =IFERROR(E42/D42,0) -> 0 | G42: =IFERROR(E42/F42,0) -> 0
A43: VARIANCE | B43: =IFERROR(B42-B41,0) -> -121000 | C43: =IFERROR(C42-C41,0) -> -0.1089 | E43: =IFERROR(E42-E41,0) -> -13176.9 | H43: =IF(E43=0,"-",IF(C43<=0,"GOOD!",IF(C43<=0.01,"CAUTION!","BAD!"))) -> GOOD! | I43: =IFERROR(IF(E43>0,"TRIM "&TEXT(ABS(E43)/D41,"#,##0")&" HRS TO HIT TARGET","ROOM FOR "&TEXT(ABS(E43)/D41,"#,##0")&" HRS IF NEEDED"),"-") -> ROOM FOR 527 HRS IF NEEDED
A45: PRODUCE
A46: FORECAST | B46: 163000 | C46: 0.1089 | D46: 25 | E46: =IFERROR(B46*C46,0) -> 17750.7 | F46: =IFERROR(E46/D46,0) -> 710.028
A47: ACTUAL | E47: =IFERROR(B47*C47,0) -> 0 | F47: =IFERROR(E47/D47,0) -> 0 | G47: =IFERROR(E47/F47,0) -> 0
A48: VARIANCE | B48: =IFERROR(B47-B46,0) -> -163000 | C48: =IFERROR(C47-C46,0) -> -0.1089 | E48: =IFERROR(E47-E46,0) -> -17750.7 | H48: =IF(E48=0,"-",IF(C48<=0,"GOOD!",IF(C48<=0.01,"CAUTION!","BAD!"))) -> GOOD! | I48: =IFERROR(IF(E48>0,"TRIM "&TEXT(ABS(E48)/D46,"#,##0")&" HRS TO HIT TARGET","ROOM FOR "&TEXT(ABS(E48)/D46,"#,##0")&" HRS IF NEEDED"),"-") -> ROOM FOR 710 HRS IF NEEDED
A50: DELI
...

Sheet MONTH 4
A1: MONTH 4 | STORE LABOR & SALES TRACKER
A3: STORE AT A GLANCE
B4: FORECAST | C4: ACTUAL | D4: VARIANCE | E4: STATUS
A5: TOTAL SALES | B5: =B82 -> 1547435 | C5: =B83 -> 0 | D5: =IFERROR(B83-B82,0) -> -1547435 | E5: =IF(B83>=B82,"GOOD!","BELOW PLAN") -> BELOW PLAN
A6: TOTAL LABOR $ | B6: =E82 -> 199464.37 | C6: =E83 -> 0 | D6: =IFERROR(E83-E82,0) -> -199464.37 | E6: =H84 -> GOOD!
A7: LABOR % | B7: =C82 -> 0.1289 | C7: =C83 -> 0 | D7: =IFERROR(C83-C82,0) -> -0.1289 | E7: =H84 -> GOOD!
A8: STORE AVG WAGE | B8: "-" | C8: =G83 -> 0 | D8: "-"
A9: TOTAL HOURS | B9: =F82 -> 7978.5749 | C9: =F83 -> 0 | D9: =IFERROR(F83-F82,0) -> -7978.5749 | E9: =H84 -> GOOD!
A12: DEPARTMENT SUMMARY
A13: DEPARTMENT | B13: FORECAST LAB$ | C13: ACTUAL LAB$ | D13: ACTUAL LAB% | E13: VAR LAB$ | F13: VAR LAB% | G13: STATUS | H13: ACTION
A14: GROCERY | B14: =E31 -> 82401.036 | C14: =E32 -> 0 | D14: =C32 -> 0 | E14: =E33 -> -82401.036 | F14: =C33 -> -0.1089 | G14: =H33 -> GOOD! | H14: =I33 -> ROOM FOR 3,296 HRS IF NEEDED
A15: MEAT | B15: =E36 -> 17750.7 | C15: =E37 -> 0 | D15: =C37 -> 0 | E15: =E38 -> -17750.7 | F15: =C38 -> -0.1089 | G15: =H38 -> GOOD! | H15: =I38 -> ROOM FOR 710 HRS IF NEEDED
A16: SEAFOOD | B16: =E41 -> 13176.9 | C16: =E42 -> 0 | D16: =C42 -> 0 | E16: =E43 -> -13176.9 | F16: =C43 -> -0.1089 | G16: =H43 -> GOOD! | H16: =I43 -> ROOM FOR 527 HRS IF NEEDED
A17: PRODUCE | B17: =E46 -> 17750.7 | C17: =E47 -> 0 | D17: =C47 -> 0 | E17: =E48 -> -17750.7 | F17: =C48 -> -0.1089 | G17: =H48 -> GOOD! | H17: =I48 -> ROOM FOR 710 HRS IF NEEDED
A18: DELI | B18: =E51 -> 14338.536 | C18: =E52 -> 0 | D18: =C52 -> 0 | E18: =E53 -> -14338.536 | F18: =C53 -> -0.1089 | G18: =H53 -> GOOD! | H18: =I53 -> ROOM FOR 574 HRS IF NEEDED
A19: BAKERY | B19: =E56 -> 14338.536 | C19: =E57 -> 0 | D19: =C57 -> 0 | E19: =E58 -> -14338.536 | F19: =C58 -> -0.1089 | G19: =H58 -> GOOD! | H19: =I58 -> ROOM FOR 574 HRS IF NEEDED
A20: FLORAL | B20: =E61 -> 834.9363 | C20: =E62 -> 0 | D20: =C62 -> 0 | E20: =E63 -> -834.9363 | F20: =C63 -> -0.1089 | G20: =H63 -> GOOD! | H20: =I63 -> ROOM FOR 33 HRS IF NEEDED
A21: STARBUCKS | B21: =E66 -> 337.59 | C21: =E67 -> 0 | D21: =C67 -> 0 | E21: =E68 -> -337.59 | F21: =C68 -> -0.1089 | G21: =H68 -> GOOD! | H21: =I68 -> ROOM FOR 14 HRS IF NEEDED
A22: ECOM | B22: =E71 -> 7586.7363 | C22: =E72 -> 0 | D22: =C72 -> 0 | E22: =E73 -> -7586.7363 | F22: =C73 -> -0.1089 | G22: =H73 -> GOOD! | H22: =I73 -> ROOM FOR 303 HRS IF NEEDED
A23: FRONT END | B23: =E76 -> 30948.7 | C23: =E77 -> 0 | D23: =C77 -> 0 | E23: =E78 -> -30948.7 | F23: =C78 -> -0.02 | G23: =H78 -> GOOD! | H23: =I78 -> ROOM FOR 1,238 HRS IF NEEDED
A24: STORE TOTAL | B24: =E82 -> 199464.37 | C24: =E83 -> 0 | D24: =C83 -> 0 | E24: =E84 -> -199464.37 | F24: =C84 -> -0.1289 | G24: =H84 -> GOOD! | H24: =I84 -> ROOM FOR 7,979 HRS IF NEEDED
A28: FULL DEPARTMENT DETAIL
B29: SALES | C29: LABOR % | D29: HRLY RATE | E29: LABOR $ | F29: HOURS | G29: AVG WAGE | H29: STATUS | I29: ACTION
A30: GROCERY
A31: FORECAST | B31: 756667 | C31: 0.1089 | D31: 25 | E31: =IFERROR(B31*C31,0) -> 82401.036 | F31: =IFERROR(E31/D31,0) -> 3296.0415
A32: ACTUAL | E32: =IFERROR(B32*C32,0) -> 0 | F32: =IFERROR(E32/D32,0) -> 0 | G32: =IFERROR(E32/F32,0) -> 0
A33: VARIANCE | B33: =IFERROR(B32-B31,0) -> -756667 | C33: =IFERROR(C32-C31,0) -> -0.1089 | E33: =IFERROR(E32-E31,0) -> -82401.036 | H33: =IF(E33=0,"-",IF(C33<=0,"GOOD!",IF(C33<=0.01,"CAUTION!","BAD!"))) -> GOOD! | I33: =IFERROR(IF(E33>0,"TRIM "&TEXT(ABS(E33)/D31,"#,##0")&" HRS TO HIT TARGET","ROOM FOR "&TEXT(ABS(E33)/D31,"#,##0")&" HRS IF NEEDED"),"-") -> ROOM FOR 3,296 HRS IF NEEDED
A35: MEAT
A36: FORECAST | B36: 163000 | C36: 0.1089 | D36: 25 | E36: =IFERROR(B36*C36,0) -> 17750.7 | F36: =IFERROR(E36/D36,0) -> 710.028
A37: ACTUAL | E37: =IFERROR(B37*C37,0) -> 0 | F37: =IFERROR(E37/D37,0) -> 0 | G37: =IFERROR(E37/F37,0) -> 0
A38: VARIANCE | B38: =IFERROR(B37-B36,0) -> -163000 | C38: =IFERROR(C37-C36,0) -> -0.1089 | E38: =IFERROR(E37-E36,0) -> -17750.7 | H38: =IF(E38=0,"-",IF(C38<=0,"GOOD!",IF(C38<=0.01,"CAUTION!","BAD!"))) -> GOOD! | I38: =IFERROR(IF(E38>0,"TRIM "&TEXT(ABS(E38)/D36,"#,##0")&" HRS TO HIT TARGET","ROOM FOR "&TEXT(ABS(E38)/D36,"#,##0")&" HRS IF NEEDED"),"-") -> ROOM FOR 710 HRS IF NEEDED
A40: SEAFOOD
A41: FORECAST | B41: 121000 | C41: 0.1089 | D41: 25 | E41: =IFERROR(B41*C41,0) -> 13176.9 | F41: =IFERROR(E41/D41,0) -> 527.076
A42: ACTUAL | E42: =IFERROR(B42*C42,0) -> 0 | F42: =IFERROR(E42/D42,0) -> 0 | G42: =IFERROR(E42/F42,0) -> 0
A43: VARIANCE | B43: =IFERROR(B42-B41,0) -> -121000 | C43: =IFERROR(C42-C41,0) -> -0.1089 | E43: =IFERROR(E42-E41,0) -> -13176.9 | H43: =IF(E43=0,"-",IF(C43<=0,"GOOD!",IF(C43<=0.01,"CAUTION!","BAD!"))) -> GOOD! | I43: =IFERROR(IF(E43>0,"TRIM "&TEXT(ABS(E43)/D41,"#,##0")&" HRS TO HIT TARGET","ROOM FOR "&TEXT(ABS(E43)/D41,"#,##0")&" HRS IF NEEDED"),"-") -> ROOM FOR 527 HRS IF NEEDED
A45: PRODUCE
A46: FORECAST | B46: 163000 | C46: 0.1089 | D46: 25 | E46: =IFERROR(B46*C46,0) -> 17750.7 | F46: =IFERROR(E46/D46,0) -> 710.028
A47: ACTUAL | E47: =IFERROR(B47*C47,0) -> 0 | F47: =IFERROR(E47/D47,0) -> 0 | G47: =IFERROR(E47/F47,0) -> 0
A48: VARIANCE | B48: =IFERROR(B47-B46,0) -> -163000 | C48: =IFERROR(C47-C46,0) -> -0.1089 | E48: =IFERROR(E47-E46,0) -> -17750.7 | H48: =IF(E48=0,"-",IF(C48<=0,"GOOD!",IF(C48<=0.01,"CAUTION!","BAD!"))) -> GOOD! | I48: =IFERROR(IF(E48>0,"TRIM "&TEXT(ABS(E48)/D46,"#,##0")&" HRS TO HIT TARGET","ROOM FOR "&TEXT(ABS(E48)/D46,"#,##0")&" HRS IF NEEDED"),"-") -> ROOM FOR 710 HRS IF NEEDED
A50: DELI
...

Sheet Q1 SUMMARY
A1: Q1 SUMMARY | STORE LABOR & SALES TRACKER
A3: WEEKS IN QUARTER: | B3: 13 | C3: Enter 13 for standard quarter or 17 for 5-week quarter
A5: QUARTERLY PERFORMANCE BY DEPARTMENT
B6: SALES | D6: LABOR $ | F6: LABOR % | H6: VARIANCE | J6: WEEKLY AVG SALES | K6: STATUS / ACTION
A7: DEPARTMENT | B7: FORECAST | C7: ACTUAL | D7: FORECAST | E7: ACTUAL | F7: FORECAST | G7: ACTUAL | H7: LAB$ VAR | I7: LAB% VAR | J7: SALES/WK | K7: STATUS | L7: ACTION
A8: GROCERY | B8: ='MONTH 1'!B31+'MONTH 2'!B31+'MONTH 3'!B31+'MONTH 4'!B31 -> 3026668 | C8: ='MONTH 1'!B32+'MONTH 2'!B32+'MONTH 3'!B32+'MONTH 4'!B32 -> 0 | D8: ='MONTH 1'!E31+'MONTH 2'!E31+'MONTH 3'!E31+'MONTH 4'!E31 -> 329604.15 | E8: ='MONTH 1'!E32+'MONTH 2'!E32+'MONTH 3'!E32+'MONTH 4'!E32 -> 0 | F8: =IFERROR(D8/B8,0) -> 0.1089 | G8: =IFERROR(E8/C8,0) -> 0 | H8: =IFERROR(E8-D8,0) -> -329604.15 | I8: =IFERROR(G8-F8,0) -> -0.1089 | J8: =IFERROR(C8/B3,0) -> 0 | K8: =IF(H8=0,"-",IF(I8<=0,"GOOD!",IF(I8<=0.01,"CAUTION!","BAD!"))) -> GOOD! | L8: =IFERROR(IF(H8>0,"TRIM "&TEXT(ABS(H8)/25,"#,##0")&" HRS TO HIT TARGET","ROOM FOR "&TEXT(ABS(H8)/25,"#,##0")&" HRS IF NEEDED"),"-") -> ROOM FOR 13,184 HRS IF NEEDED
A9: MEAT | B9: ='MONTH 1'!B36+'MONTH 2'!B36+'MONTH 3'!B36+'MONTH 4'!B36 -> 652000 | C9: ='MONTH 1'!B37+'MONTH 2'!B37+'MONTH 3'!B37+'MONTH 4'!B37 -> 0 | D9: ='MONTH 1'!E36+'MONTH 2'!E36+'MONTH 3'!E36+'MONTH 4'!E36 -> 71002.8 | E9: ='MONTH 1'!E37+'MONTH 2'!E37+'MONTH 3'!E37+'MONTH 4'!E37 -> 0 | F9: =IFERROR(D9/B9,0) -> 0.1089 | G9: =IFERROR(E9/C9,0) -> 0 | H9: =IFERROR(E9-D9,0) -> -71002.8 | I9: =IFERROR(G9-F9,0) -> -0.1089 | J9: =IFERROR(C9/B3,0) -> 0 | K9: =IF(H9=0,"-",IF(I9<=0,"GOOD!",IF(I9<=0.01,"CAUTION!","BAD!"))) -> GOOD! | L9: =IFERROR(IF(H9>0,"TRIM "&TEXT(ABS(H9)/25,"#,##0")&" HRS TO HIT TARGET","ROOM FOR "&TEXT(ABS(H9)/25,"#,##0")&" HRS IF NEEDED"),"-") -> ROOM FOR 2,840 HRS IF NEEDED
A10: SEAFOOD | B10: ='MONTH 1'!B41+'MONTH 2'!B41+'MONTH 3'!B41+'MONTH 4'!B41 -> 484000 | C10: ='MONTH 1'!B42+'MONTH 2'!B42+'MONTH 3'!B42+'MONTH 4'!B42 -> 0 | D10: ='MONTH 1'!E41+'MONTH 2'!E41+'MONTH 3'!E41+'MONTH 4'!E41 -> 52707.6 | E10: ='MONTH 1'!E42+'MONTH 2'!E42+'MONTH 3'!E42+'MONTH 4'!E42 -> 0 | F10: =IFERROR(D10/B10,0) -> 0.1089 | G10: =IFERROR(E10/C10,0) -> 0 | H10: =IFERROR(E10-D10,0) -> -52707.6 | I10: =IFERROR(G10-F10,0) -> -0.1089 | J10: =IFERROR(C10/B3,0) -> 0 | K10: =IF(H10=0,"-",IF(I10<=0,"GOOD!",IF(I10<=0.01,"CAUTION!","BAD!"))) -> GOOD! | L10: =IFERROR(IF(H10>0,"TRIM "&TEXT(ABS(H10)/25,"#,##0")&" HRS TO HIT TARGET","ROOM FOR "&TEXT(ABS(H10)/25,"#,##0")&" HRS IF NEEDED"),"-") -> ROOM FOR 2,108 HRS IF NEEDED
A11: PRODUCE | B11: ='MONTH 1'!B46+'MONTH 2'!B46+'MONTH 3'!B46+'MONTH 4'!B46 -> 652000 | C11: ='MONTH 1'!B47+'MONTH 2'!B47+'MONTH 3'!B47+'MONTH 4'!B47 -> 0 | D11: ='MONTH 1'!E46+'MONTH 2'!E46+'MONTH 3'!E46+'MONTH 4'!E46 -> 71002.8 | E11: ='MONTH 1'!E47+'MONTH 2'!E47+'MONTH 3'!E47+'MONTH 4'!E47 -> 0 | F11: =IFERROR(D11/B11,0) -> 0.1089 | G11: =IFERROR(E11/C11,0) -> 0 | H11: =IFERROR(E11-D11,0) -> -71002.8 | I11: =IFERROR(G11-F11,0) -> -0.1089 | J11: =IFERROR(C11/B3,0) -> 0 | K11: =IF(H11=0,"-",IF(I11<=0,"GOOD!",IF(I11<=0.01,"CAUTION!","BAD!"))) -> GOOD! | L11: =IFERROR(IF(H11>0,"TRIM "&TEXT(ABS(H11)/25,"#,##0")&" HRS TO HIT TARGET","ROOM FOR "&TEXT(ABS(H11)/25,"#,##0")&" HRS IF NEEDED"),"-") -> ROOM FOR 2,840 HRS IF NEEDED
A12: DELI | B12: ='MONTH 1'!B51+'MONTH 2'!B51+'MONTH 3'!B51+'MONTH 4'!B51 -> 526668 | C12: ='MONTH 1'!B52+'MONTH 2'!B52+'MONTH 3'!B52+'MONTH 4'!B52 -> 0 | D12: ='MONTH 1'!E51+'MONTH 2'!E51+'MONTH 3'!E51+'MONTH 4'!E51 -> 57354.145 | E12: ='MONTH 1'!E52+'MONTH 2'!E52+'MONTH 3'!E52+'MONTH 4'!E52 -> 0 | F12: =IFERROR(D12/B12,0) -> 0.1089 | G12: =IFERROR(E12/C12,0) -> 0 | H12: =IFERROR(E12-D12,0) -> -57354.145 | I12: =IFERROR(G12-F12,0) -> -0.1089 | J12: =IFERROR(C12/B3,0) -> 0 | K12: =IF(H12=0,"-",IF(I12<=0,"GOOD!",IF(I12<=0.01,"CAUTION!","BAD!"))) -> GOOD! | L12: =IFERROR(IF(H12>0,"TRIM "&TEXT(ABS(H12)/25,"#,##0")&" HRS TO HIT TARGET","ROOM FOR "&TEXT(ABS(H12)/25,"#,##0")&" HRS IF NEEDED"),"-") -> ROOM FOR 2,294 HRS IF NEEDED
A13: BAKERY | B13: ='MONTH 1'!B56+'MONTH 2'!B56+'MONTH 3'!B56+'MONTH 4'!B56 -> 526668 | C13: ='MONTH 1'!B57+'MONTH 2'!B57+'MONTH 3'!B57+'MONTH 4'!B57 -> 0 | D13: ='MONTH 1'!E56+'MONTH 2'!E56+'MONTH 3'!E56+'MONTH 4'!E56 -> 57354.145 | E13: ='MONTH 1'!E57+'MONTH 2'!E57+'MONTH 3'!E57+'MONTH 4'!E57 -> 0 | F13: =IFERROR(D13/B13,0) -> 0.1089 | G13: =IFERROR(E13/C13,0) -> 0 | H13: =IFERROR(E13-D13,0) -> -57354.145 | I13: =IFERROR(G13-F13,0) -> -0.1089 | J13: =IFERROR(C13/B3,0) -> 0 | K13: =IF(H13=0,"-",IF(I13<=0,"GOOD!",IF(I13<=0.01,"CAUTION!","BAD!"))) -> GOOD! | L13: =IFERROR(IF(H13>0,"TRIM "&TEXT(ABS(H13)/25,"#,##0")&" HRS TO HIT TARGET","ROOM FOR "&TEXT(ABS(H13)/25,"#,##0")&" HRS IF NEEDED"),"-") -> ROOM FOR 2,294 HRS IF NEEDED
A14: FLORAL | B14: ='MONTH 1'!B61+'MONTH 2'!B61+'MONTH 3'!B61+'MONTH 4'!B61 -> 30668 | C14: ='MONTH 1'!B62+'MONTH 2'!B62+'MONTH 3'!B62+'MONTH 4'!B62 -> 0 | D14: ='MONTH 1'!E61+'MONTH 2'!E61+'MONTH 3'!E61+'MONTH 4'!E61 -> 3339.7452 | E14: ='MONTH 1'!E62+'MONTH 2'!E62+'MONTH 3'!E62+'MONTH 4'!E62 -> 0 | F14: =IFERROR(D14/B14,0) -> 0.1089 | G14: =IFERROR(E14/C14,0) -> 0 | H14: =IFERROR(E14-D14,0) -> -3339.7452 | I14: =IFERROR(G14-F14,0) -> -0.1089 | J14: =IFERROR(C14/B3,0) -> 0 | K14: =IF(H14=0,"-",IF(I14<=0,"GOOD!",IF(I14<=0.01,"CAUTION!","BAD!"))) -> GOOD! | L14: =IFERROR(IF(H14>0,"TRIM "&TEXT(ABS(H14)/25,"#,##0")&" HRS TO HIT TARGET","ROOM FOR "&TEXT(ABS(H14)/25,"#,##0")&" HRS IF NEEDED"),"-") -> ROOM FOR 134 HRS IF NEEDED
A15: STARBUCKS | B15: ='MONTH 1'!B66+'MONTH 2'!B66+'MONTH 3'!B66+'MONTH 4'!B66 -> 12400 | C15: ='MONTH 1'!B67+'MONTH 2'!B67+'MONTH 3'!B67+'MONTH 4'!B67 -> 0 | D15: ='MONTH 1'!E66+'MONTH 2'!E66+'MONTH 3'!E66+'MONTH 4'!E66 -> 1350.36 | E15: ='MONTH 1'!E67+'MONTH 2'!E67+'MONTH 3'!E67+'MONTH 4'!E67 -> 0 | F15: =IFERROR(D15/B15,0) -> 0.1089 | G15: =IFERROR(E15/C15,0) -> 0 | H15: =IFERROR(E15-D15,0) -> -1350.36 | I15: =IFERROR(G15-F15,0) -> -0.1089 | J15: =IFERROR(C15/B3,0) -> 0 | K15: =IF(H15=0,"-",IF(I15<=0,"GOOD!",IF(I15<=0.01,"CAUTION!","BAD!"))) -> GOOD! | L15: =IFERROR(IF(H15>0,"TRIM "&TEXT(ABS(H15)/25,"#,##0")&" HRS TO HIT TARGET","ROOM FOR "&TEXT(ABS(H15)/25,"#,##0")&" HRS IF NEEDED"),"-") -> ROOM FOR 54 HRS IF NEEDED
A16: ECOM | B16: ='MONTH 1'!B71+'MONTH 2'!B71+'MONTH 3'!B71+'MONTH 4'!B71 -> 278668 | C16: ='MONTH 1'!B72+'MONTH 2'!B72+'MONTH 3'!B72+'MONTH 4'!B72 -> 0 | D16: ='MONTH 1'!E71+'MONTH 2'!E71+'MONTH 3'!E71+'MONTH 4'!E71 -> 30346.945 | E16: ='MONTH 1'!E72+'MONTH 2'!E72+'MONTH 3'!E72+'MONTH 4'!E72 -> 0 | F16: =IFERROR(D16/B16,0) -> 0.1089 | G16: =IFERROR(E16/C16,0) -> 0 | H16: =IFERROR(E16-D16,0) -> -30346.945 | I16: =IFERROR(G16-F16,0) -> -0.1089 | J16: =IFERROR(C16/B3,0) -> 0 | K16: =IF(H16=0,"-",IF(I16<=0,"GOOD!",IF(I16<=0.01,"CAUTION!","BAD!"))) -> GOOD! | L16: =IFERROR(IF(H16>0,"TRIM "&TEXT(ABS(H16)/25,"#,##0")&" HRS TO HIT TARGET","ROOM FOR "&TEXT(ABS(H16)/25,"#,##0")&" HRS IF NEEDED"),"-") -> ROOM FOR 1,214 HRS IF NEEDED
A17: FRONT END | B17: - | C17: - | D17: ='MONTH 1'!E76+'MONTH 2'!E76+'MONTH 3'!E76+'MONTH 4'!E76 -> 123794.8 | E17: ='MONTH 1'!E77+'MONTH 2'!E77+'MONTH 3'!E77+'MONTH 4'!E77 -> 0 | F17: =IFERROR(D17/('MONTH 1'!B82+'MONTH 2'!B82+'MONTH 3'!B82+'MONTH 4'!B82),0) -> 0.02 | G17: =IFERROR(E17/('MONTH 1'!B83+'MONTH 2'!B83+'MONTH 3'!B83+'MONTH 4'!B83),0) -> 0 | H17: =IFERROR(E17-D17,0) -> -123794.8 | I17: =IFERROR(G17-F17,0) -> -0.02 | J17: - | K17: =IF(H17=0,"-",IF(I17<=0,"GOOD!",IF(I17<=0.01,"CAUTION!","BAD!"))) -> GOOD! | L17: =IFERROR(IF(H17>0,"TRIM "&TEXT(ABS(H17)/25,"#,##0")&" HRS TO HIT TARGET","ROOM FOR "&TEXT(ABS(H17)/25,"#,##0")&" HRS IF NEEDED"),"-") -> ROOM FOR 4,952 HRS IF NEEDED
A19: STORE TOTAL | B19: =('MONTH 1'!B82+'MONTH 2'!B82+'MONTH 3'!B82+'MONTH 4'!B82) -> 6189740 | C19: =('MONTH 1'!B83+'MONTH 2'!B83+'MONTH 3'!B83+'MONTH 4'!B83) -> 0 | D19: =('MONTH 1'!E82+'MONTH 2'!E82+'MONTH 3'!E82+'MONTH 4'!E82) -> 797857.49 | E19: =('MONTH 1'!E83+'MONTH 2'!E83+'MONTH 3'!E83+'MONTH 4'!E83) -> 0 | F19: =IFERROR(D19/B19,0) -> 0.1289 | G19: =IFERROR(E19/C19,0) -> 0 | H19: =IFERROR(E19-D19,0) -> -797857.49 | I19: =IFERROR(G19-F19,0) -> -0.1289 | J19: =IFERROR(C19/B3,0) -> 0 | K19: =IF(H19=0,"-",IF(I19<=0,"GOOD!",IF(I19<=0.01,"CAUTION!","BAD!"))) -> GOOD! | L19: =IFERROR(IF(H19>0,"TRIM "&TEXT(ABS(H19)/IFERROR(('MONTH 1'!E82+'MONTH 2'!E82+'MONTH 3'!E82+'MONTH 4'!E82)/('MONTH 1'!F82+'MONTH 2'!F82+'MONTH 3'!F82+'MONTH 4'!F82),25),"#,##0")&" HRS TO HIT TARGET","ROOM FOR "&TEXT(ABS(H19)/IFERROR(('MONTH 1'!E82+'MONTH 2'!E82+'MONTH 3'!E82+'MONTH 4'!E82)/('MONTH 1'!F82+'MONTH 2'!F82+'MONTH 3'!F82+'MONTH 4'!F82),25),"#,##0")&" HRS IF NEEDED"),"-") -> ROOM FOR 31,914 HRS IF NEEDED
A21: STORE Q1 AVG WAGE: | C21: =IFERROR(('MONTH 1'!E83+'MONTH 2'!E83+'MONTH 3'!E83+'MONTH 4'!E83)/('MONTH 1'!F83+'MONTH 2'!F83+'MONTH 3'!F83+'MONTH 4'!F83),0) -> 0
